Workbook

Sheet راهنما
A1: مدل مالی یکپارچه FIS: الگوی آموزشی
A2: آموزشی، نه توصیه سرمایه‌گذاری. اعداد فعلی یک شرکت فرضی هستند؛ با اعداد شرکت خودتان از کدال جایگزین کنید.
A4: ترتیب کار
A5: ۱. برگه «تاریخی»: دو سال آخر صورت‌های مالی را از کدال وارد کنید (فقط سلول‌های آبی).
A6: ۲. برگه «مفروضات»: سناریو (۱ بد، ۲ پایه، ۳ خوب)، تورم، مالیات، دوره‌های وصول و پرداخت، و نرخ‌های تنزیل را تنظیم کنید.
A7: ۳. برگه «مدل»: صورت سود و زیان، ترازنامه و جریان وجوه نقد ۵ سال آینده خودکار ساخته می‌شود. ردیف «کنترل تراز» باید صفر باشد.
A8: ۴. برگه «ارزش‌گذاری»: FCFF، نرخ تنزیل، ارزش نهایی، جدول حساسیت، ضریب EV/EBITDA و جدول دامنه ارزش.
A9: ۵. سناریو را ۱، ۲ و ۳ کنید و ارزش هر سهم را در جدول «ثبت سناریوها» تایپ کنید تا ارزش وزنی و دامنه به دست آید.
A11: رنگ‌ها
A12: آبی: ورودی که خودتان وارد می‌کنید · سیاه: فرمول · سبز: پیوند به برگه دیگر · زمینه زرد: مفروضات کلیدی که بیشترین اثر را دارند.
A14: واحدها و علامت‌ها
A15: همه مبالغ به میلیون ریال، مثل کدال. EPS و قیمت هر سهم به ریال. تعداد سهام به میلیون سهم (سرمایه ÷ ۱,۰۰۰).
... A22: نتیجه یک دامنه است، نه یک عدد. پیش از هر تصمیم، کیفیت سود (بخش ۴.۱) و پرچم‌های قرمز (بخش ۴.۷) را بررسی کنید.

Sheet تاریخی
A1: داده‌های تاریخی از کدال (میلیون ریال)
A2: نمونه فرضی؛ ستون‌های B و C را با دو سال آخر شرکت خودتان جایگزین کنید.
A3: شرح | B3: دو سال قبل | C3: سال پایه | D3: منبع در کدال
A4: مقدار فروش (تن) | B4: 195000 | C4: 200000 | D4: گزارش فعالیت ماهانه (جمع ۱۲ ماه)
A5: درآمدهای عملیاتی | B5: 3700000 | C5: 5000000 | D5: صورت سود و زیان
A6: بهای تمام‌شده درآمدهای عملیاتی (مثبت) | B6: 2650000 | C6: 3500000 | D6: صورت سود و زیان
A7: هزینه‌های فروش، اداری و عمومی (مثبت) | B7: 230000 | C7: 300000 | D7: صورت سود و زیان
A8: سایر درآمدها و هزینه‌های عملیاتی (خالص، مثبت = درآمد) | B8: -20000 | C8: -30000 | D8: صورت سود و زیان
A9: سود عملیاتی | B9: =B5-B6-B7+B8 -> 800000 | C9: =C5-C6-C7+C8 -> 1170000 | D9: فرمول
A10: هزینه‌های مالی (مثبت) | B10: 210000 | C10: 230000 | D10: صورت سود و زیان
A11: درآمدهای غیرعملیاتی (خالص) | B11: 30000 | C11: 50000 | D11: صورت سود و زیان
A12: سود قبل از مالیات | B12: =B9-B10+B11 -> 620000 | C12: =C9-C10+C11 -> 990000 | D12: فرمول
A13: مالیات (مثبت) | B13: 120000 | C13: 160000 | D13: صورت سود و زیان
A14: سود خالص | B14: =B12-B13 -> 500000 | C14: =C12-C13 -> 830000 | D14: فرمول
A15: سرمایه (میلیون ریال) | B15: 4000000 | C15: 4000000 | D15: سرصفحه گزارش
A16: تعداد سهام (میلیون سهم) | B16: =B15/1000 -> 4000 | C16: =C15/1000 -> 4000 | D16: فرمول (سرمایه ÷ ۱,۰۰۰)
A17: سود هر سهم (ریال) | B17: =IF(B16=0,0,B14/B16) -> 125 | C17: =IF(C16=0,0,C14/C16) -> 207.5 | D17: فرمول
A18: ترازنامه
A19: موجودی نقد و سپرده | B19: 250000 | C19: 300000 | D19: صورت وضعیت مالی
A20: دریافتنی‌های تجاری | B20: 600000 | C20: 820000 | D20: صورت وضعیت مالی
A21: موجودی مواد و کالا | B21: 650000 | C21: 860000 | D21: صورت وضعیت مالی
A22: دارایی‌های ثابت مشهود (خالص) | B22: 2300000 | C22: 2500000 | D22: صورت وضعیت مالی
A23: سایر دارایی‌ها | B23: 120000 | C23: 150000 | D23: صورت وضعیت مالی (جمع بقیه)
A24: جمع دارایی‌ها | B24: =B19+B20+B21+B22+B23 -> 3920000 | C24: =C19+C20+C21+C22+C23 -> 4630000 | D24: فرمول
A25: پرداختنی‌های تجاری | B25: 330000 | C25: 430000 | D25: صورت وضعیت مالی
A26: تسهیلات مالی | B26: 900000 | C26: 1000000 | D26: صورت وضعیت مالی و یادداشت تسهیلات
A27: سایر بدهی‌ها | B27: 170000 | C27: 200000 | D27: صورت وضعیت مالی (جمع بقیه)
A28: جمع حقوق مالکانه | B28: 2520000 | C28: 3000000 | D28: صورت وضعیت مالی
A29: کنترل تراز (باید صفر باشد) | B29: =B24-B25-B26-B27-B28 -> 0 | C29: =C24-C25-C26-C27-C28 -> 0 | D29: فرمول
A30: جریان وجوه نقد
A31: جریان خالص نقد عملیاتی | B31: 620000 | C31: 900000 | D31: صورت جریان‌های نقدی
A32: پرداخت برای خرید دارایی ثابت (CAPEX، مثبت) | B32: 380000 | C32: 450000 | D32: صورت جریان‌های نقدی
A33: استهلاک | B33: 200000 | C33: 230000 | D33: یادداشت دارایی‌های ثابت
A35: نسبت‌ها (فرمول)
A36: حاشیه سود ناخالص | B36: =IF(B5=0,0,(B5-B6)/B5) -> 0.28378378 | C36: =IF(C5=0,0,(C5-C6)/C5) -> 0.3
A37: حاشیه سود عملیاتی | B37: =IF(B5=0,0,B9/B5) -> 0.21621622 | C37: =IF(C5=0,0,C9/C5) -> 0.234
A38: نرخ مؤثر مالیات | B38: =IF(B12=0,0,B13/B12) -> 0.19354839 | C38: =IF(C12=0,0,C13/C12) -> 0.16161616
A39: نقد عملیاتی ÷ سود خالص (کیفیت سود) | B39: =IF(B14=0,0,B31/B14) -> 1.24 | C39: =IF(C14=0,0,C31/C14) -> 1.0843373
A40: دوره وصول (روز) | B40: =IF(B5=0,0,B20/B5*365) -> 59.189189 | C40: =IF(C5=0,0,C20/C5*365) -> 59.86
A41: دوره نگهداری موجودی (روز) | B41: =IF(B6=0,0,B21/B6*365) -> 89.528302 | C41: =IF(C6=0,0,C21/C6*365) -> 89.685714
...

Sheet مفروضات
A1: مفروضات
A2: فقط سلول‌های آبی را تغییر دهید. زمینه زرد = مفروضات کلیدی.
A4: سناریوی فعال (۱ بد، ۲ پایه، ۳ خوب) | B4: 2 | C4: =CHOOSE($B$4,"بد","پایه","خوب") -> پایه
A6: اهرم سناریو | B6: فعال | C6: بد | D6: پایه | E6: خوب
A7: رشد سالانه مقدار فروش | B7: =CHOOSE($B$4,C7,D7,E7) -> 0.03 | C7: 0 | D7: 0.03 | E7: 0.04
A8: تغییر واقعی سالانه نرخ فروش (بالاتر از تورم؛ نرخ ارز، قیمت جهانی) | B8: =CHOOSE($B$4,C8,D8,E8) -> 0 | C8: -0.01 | D8: 0 | E8: 0.005
A9: تغییر واقعی سالانه هزینه متغیر هر تن (خوراک، مواد) | B9: =CHOOSE($B$4,C9,D9,E9) -> 0 | C9: 0.01 | D9: 0 | E9: -0.005
A11: مفروضات سالانه | B11: سال اول | C11: سال دوم | D11: سال سوم | E11: سال چهارم | F11: سال پنجم
A12: تورم سالانه | B12: 0.35 | C12: 0.3 | D12: 0.28 | E12: 0.25 | F12: 0.25
A13: نرخ مؤثر مالیات (پایان معافیت را اینجا وارد کنید) | B13: 0.15 | C13: 0.15 | D13: 0.25 | E13: 0.25 | F13: 0.25
A14: CAPEX توسعه (اسمی، میلیون ریال) | B14: 0 | C14: 0 | D14: 0 | E14: 0 | F14: 0
A15: خالص استقراض جدید (بازپرداخت = منفی) | B15: 0 | C15: 0 | D15: 0 | E15: 0 | F15: 0
A16: افزایش سرمایه نقدی به ارزش اسمی (میلیون ریال) | B16: 0 | C16: 0 | D16: 0 | E16: 0 | F16: 0
A18: مفروضات ثابت | B18: مقدار | C18: توضیح
A19: سهم هزینه متغیر از بهای تمام‌شده (سال پایه، بدون استهلاک) | B19: 0.8 | C19: از یادداشت بهای تمام‌شده: مواد و خوراک ÷ کل
A20: هزینه‌های فروش، اداری و عمومی (درصد فروش) | B20: 0.06 | C20: میانگین دو سال تاریخی
A21: سایر اقلام عملیاتی (درصد فروش، مثبت = درآمد) | B21: 0 | C21: معمولاً صفر فرض می‌شود
A22: نرخ استهلاک (درصد دارایی ثابت خالص ابتدای سال) | B22: 0.1 | C22: استهلاک ÷ دارایی ثابت سال قبل
A23: CAPEX نگهداشت به قیمت سال پایه | B23: 250000 | C23: به قیمت روز جایگزینی، نه برابر استهلاک دفتری
A24: دوره وصول دریافتنی‌ها (روز) | B24: 60 | C24: برگه تاریخی
A25: دوره نگهداری موجودی (روز) | B25: 90 | C25: برگه تاریخی
A26: دوره پرداخت (روز) | B26: 45 | C26: برگه تاریخی
A27: نرخ سود تسهیلات | B27: 0.23 | C27: هزینه مالی ÷ میانگین تسهیلات (یادداشت تسهیلات)
A28: نرخ سود سپرده (روی نقد ابتدای سال) | B28: 0.2 | C28: نمونه؛ بررسی کنید
A29: نسبت تقسیم سود (از سود سال قبل) | B29: 0.6 | C29: سابقه مجامع
A31: ارزش‌گذاری | B31: مقدار | C31: توضیح
A32: نرخ بدون ریسک اسمی (بازده اخزا ۲ تا ۳ ساله) | B32: 0.3 | C32: نمونه؛ نرخ روز را از فرابورس یا tsetmc بگیرید
A33: صرف ریسک سهام | B33: 0.07 | C33: قضاوت؛ معمولاً بین پنج تا ده درصد و برای همه شرکت‌ها یکسان
A34: صرف ریسک خاص شرکت | B34: 0.02 | C34: نقدشوندگی کم، وابستگی به مصوبه، بدهی ارزی، حاکمیت شرکتی
A35: هزینه بدهی قبل از مالیات | B35: 0.23 | C35: همان نرخ مؤثر تسهیلات
A36: وزن بدهی در ساختار سرمایه (ارزش بازار) | B36: 0.2 | C36: بدهی ÷ (بدهی + ارزش بازار سهام)
A37: نرخ مالیات برای صرفه مالیاتی بدهی | B37: 0.25 | C37: نرخ مؤثر بلندمدت
A38: تورم بلندمدت (برای ارزش نهایی) | B38: 0.25 | C38: فرض بلندمدت
A39: رشد نهایی واقعی | B39: 0.01 | C39: بیشتر از دو درصد نگیرید
A40: قیمت بازار هر سهم (ریال) | B40: 2000 | C40: از tsetmc
A41: ارزش بازار سرمایه‌گذاری‌های غیرعملیاتی | B41: 0 | C41: سهام بورسی و املاک غیرعملیاتی
A42: EV/EBITDA هم‌گروه‌ها: پایین | B42: 4 | C42: روی EBITDA سال آینده هم‌گروه‌ها؛ ۴ تا ۶ شرکت با محصول و حساسیت ارزی مشابه
A43: EV/EBITDA هم‌گروه‌ها: میانه | B43: 5 | C43: میانه، نه میانگین
A44: EV/EBITDA هم‌گروه‌ها: بالا | B44: 6

Sheet مدل
A1: مدل یکپارچه (میلیون ریال، اسمی)
A2: سال پایه از برگه تاریخی؛ سال‌های اول تا پنجم از مفروضات. ردیف کنترل تراز باید صفر باشد.
A3: شرح | B3: سال پایه | C3: سال اول | D3: سال دوم | E3: سال سوم | F3: سال چهارم | G3: سال پنجم
A4: شاخص‌ها
A5: تورم | C5: =مفروضات!B12 -> 0.35 | D5: =مفروضات!C12 -> 0.3 | E5: =مفروضات!D12 -> 0.28 | F5: =مفروضات!E12 -> 0.25 | G5: =مفروضات!F12 -> 0.25
A6: شاخص قیمت (پایه = ۱) | B6: 1 | C6: =B6*(1+C5) -> 1.35 | D6: =C6*(1+D5) -> 1.755 | E6: =D6*(1+E5) -> 2.2464 | F6: =E6*(1+F5) -> 2.808 | G6: =F6*(1+G5) -> 3.51
A7: عملیات
A8: مقدار فروش (تن) | B8: =تاریخی!$C$4 -> 200000 | C8: =B8*(1+مفروضات!$B$7) -> 206000 | D8: =C8*(1+مفروضات!$B$7) -> 212180 | E8: =D8*(1+مفروضات!$B$7) -> 218545.4 | F8: =E8*(1+مفروضات!$B$7) -> 225101.76 | G8: =F8*(1+مفروضات!$B$7) -> 231854.81
A9: نرخ فروش هر تن (میلیون ریال) | B9: =IF(تاریخی!$C$4=0,0,تاریخی!$C$5/تاریخی!$C$4) -> 25 | C9: =B9*(1+C5)*(1+مفروضات!$B$8) -> 33.75 | D9: =C9*(1+D5)*(1+مفروضات!$B$8) -> 43.875 | E9: =D9*(1+E5)*(1+مفروضات!$B$8) -> 56.16 | F9: =E9*(1+F5)*(1+مفروضات!$B$8) -> 70.2 | G9: =F9*(1+G5)*(1+مفروضات!$B$8) -> 87.75
A10: هزینه متغیر هر تن (میلیون ریال) | B10: =IF(تاریخی!$C$4=0,0,(تاریخی!$C$6-تاریخی!$C$33)*مفروضات!$B$19/تاریخی!$C$4) -> 13.08 | C10: =B10*(1+C5)*(1+مفروضات!$B$9) -> 17.658 | D10: =C10*(1+D5)*(1+مفروضات!$B$9) -> 22.9554 | E10: =D10*(1+E5)*(1+مفروضات!$B$9) -> 29.382912 | F10: =E10*(1+F5)*(1+مفروضات!$B$9) -> 36.72864 | G10: =F10*(1+G5)*(1+مفروضات!$B$9) -> 45.9108
A11: هزینه ثابت نقدی تولید | B11: =(تاریخی!$C$6-تاریخی!$C$33)*(1-مفروضات!$B$19) -> 654000 | C11: =B11*(1+C5) -> 882900 | D11: =C11*(1+D5) -> 1147770 | E11: =D11*(1+E5) -> 1469145.6 | F11: =E11*(1+F5) -> 1836432 | G11: =F11*(1+G5) -> 2295540
A12: صورت سود و زیان
A13: درآمدهای عملیاتی | B13: =تاریخی!$C$5 -> 5000000 | C13: =C8*C9 -> 6952500 | D13: =D8*D9 -> 9309397.5 | E13: =E8*E9 -> 12273510 | F13: =F8*F9 -> 15802144 | G13: =G8*G9 -> 20345260
A14: بهای تمام‌شده (شامل استهلاک) | B14: =تاریخی!$C$6 -> 3500000 | C14: =C8*C10+C11+C15 -> 4770448 | D14: =D8*D10+D11+D15 -> 6277196.8 | E14: =E8*E10+E11+E15 -> 8167395.9 | F14: =F8*F10+F11+F15 -> 10409349 | G14: =G8*G10+G11+G15 -> 13285092
A15: استهلاک | B15: =تاریخی!$C$33 -> 230000 | C15: =B33*مفروضات!$B$22 -> 250000 | D15: =C33*مفروضات!$B$22 -> 258750 | E15: =D33*مفروضات!$B$22 -> 276750 | F15: =E33*مفروضات!$B$22 -> 305235 | G15: =F33*مفروضات!$B$22 -> 344911.5
A16: سود ناخالص | B16: =B13-B14 -> 1500000 | C16: =C13-C14 -> 2182052 | D16: =D13-D14 -> 3032200.7 | E16: =E13-E14 -> 4106113.8 | F16: =F13-F14 -> 5392795.1 | G16: =G13-G14 -> 7060168.5
A17: هزینه‌های فروش، اداری و عمومی | B17: =تاریخی!$C$7 -> 300000 | C17: =C13*مفروضات!$B$20 -> 417150 | D17: =D13*مفروضات!$B$20 -> 558563.85 | E17: =E13*مفروضات!$B$20 -> 736410.58 | F17: =F13*مفروضات!$B$20 -> 948128.62 | G17: =G13*مفروضات!$B$20 -> 1220715.6
A18: سایر اقلام عملیاتی (خالص) | B18: =تاریخی!$C$8 -> -30000 | C18: =C13*مفروضات!$B$21 -> 0 | D18: =D13*مفروضات!$B$21 -> 0 | E18: =E13*مفروضات!$B$21 -> 0 | F18: =F13*مفروضات!$B$21 -> 0 | G18: =G13*مفروضات!$B$21 -> 0
A19: سود عملیاتی (EBIT) | B19: =B16-B17+B18 -> 1170000 | C19: =C16-C17+C18 -> 1764902 | D19: =D16-D17+D18 -> 2473636.9 | E19: =E16-E17+E18 -> 3369703.2 | F19: =F16-F17+F18 -> 4444666.5 | G19: =G16-G17+G18 -> 5839452.9
A20: EBITDA | B20: =B19+B15 -> 1400000 | C20: =C19+C15 -> 2014902 | D20: =D19+D15 -> 2732386.9 | E20: =E19+E15 -> 3646453.2 | F20: =F19+F15 -> 4749901.5 | G20: =G19+G15 -> 6184364.4
A21: هزینه‌های مالی | B21: =تاریخی!$C$10 -> 230000 | C21: =(B37+C37)/2*مفروضات!$B$27 -> 230000 | D21: =(C37+D37)/2*مفروضات!$B$27 -> 230000 | E21: =(D37+E37)/2*مفروضات!$B$27 -> 230000 | F21: =(E37+F37)/2*مفروضات!$B$27 -> 230000 | G21: =(F37+G37)/2*مفروضات!$B$27 -> 230000
A22: درآمد سود سپرده و غیرعملیاتی | B22: =تاریخی!$C$11 -> 50000 | C22: =MAX(0,B30)*مفروضات!$B$28 -> 60000 | D22: =MAX(0,C30)*مفروضات!$B$28 -> 117830.51 | E22: =MAX(0,D30)*مفروضات!$B$28 -> 205960.21 | F22: =MAX(0,E30)*مفروضات!$B$28 -> 265912.15 | G22: =MAX(0,F30)*مفروضات!$B$28 -> 386245.32
A23: سود قبل از مالیات | B23: =B19-B21+B22 -> 990000 | C23: =C19-C21+C22 -> 1594902 | D23: =D19-D21+D22 -> 2361467.4 | E23: =E19-E21+E22 -> 3345663.4 | F23: =F19-F21+F22 -> 4480578.6 | G23: =G19-G21+G22 -> 5995698.2
A24: مالیات | B24: =تاریخی!$C$13 -> 160000 | C24: =MAX(0,C23)*مفروضات!B13 -> 239235.3 | D24: =MAX(0,D23)*مفروضات!C13 -> 354220.11 | E24: =MAX(0,E23)*مفروضات!D13 -> 836415.86 | F24: =MAX(0,F23)*مفروضات!E13 -> 1120144.7 | G24: =MAX(0,G23)*مفروضات!F13 -> 1498924.5
A25: سود خالص | B25: =B23-B24 -> 830000 | C25: =C23-C24 -> 1355666.7 | D25: =D23-D24 -> 2007247.3 | E25: =E23-E24 -> 2509247.6 | F25: =F23-F24 -> 3360434 | G25: =G23-G24 -> 4496773.6
A26: تعداد سهام (میلیون) | B26: =تاریخی!$C$16 -> 4000 | C26: =B26+مفروضات!B16/1000 -> 4000 | D26: =C26+مفروضات!C16/1000 -> 4000 | E26: =D26+مفروضات!D16/1000 -> 4000 | F26: =E26+مفروضات!E16/1000 -> 4000 | G26: =F26+مفروضات!F16/1000 -> 4000
A27: سود هر سهم (ریال) | B27: =IF(B26=0,0,B25/B26) -> 207.5 | C27: =IF(C26=0,0,C25/C26) -> 338.91667 | D27: =IF(D26=0,0,D25/D26) -> 501.81182 | E27: =IF(E26=0,0,E25/E26) -> 627.3119 | F27: =IF(F26=0,0,F25/F26) -> 840.10849 | G27: =IF(G26=0,0,G25/G26) -> 1124.1934
A28: سود تقسیمی پرداختی | C28: =MAX(0,B25)*مفروضات!$B$29 -> 498000 | D28: =MAX(0,C25)*مفروضات!$B$29 -> 813400.02 | E28: =MAX(0,D25)*مفروضات!$B$29 -> 1204348.4 | F28: =MAX(0,E25)*مفروضات!$B$29 -> 1505548.5 | G28: =MAX(0,F25)*مفروضات!$B$29 -> 2016260.4
A29: ترازنامه
A30: موجودی نقد | B30: =تاریخی!$C$19 -> 300000 | C30: =B30+C51 -> 589152.56 | D30: =C30+D51 -> 1029801.1 | E30: =D30+E51 -> 1329560.7 | F30: =E30+F51 -> 1931226.6 | G30: =F30+G51 -> 2777794.1
A31: دریافتنی‌های تجاری | B31: =تاریخی!$C$20 -> 820000 | C31: =C13*مفروضات!$B$24/365 -> 1142876.7 | D31: =D13*مفروضات!$B$24/365 -> 1530311.9 | E31: =E13*مفروضات!$B$24/365 -> 2017563.2 | F31: =F13*مفروضات!$B$24/365 -> 2597612.7 | G31: =G13*مفروضات!$B$24/365 -> 3344426.3
A32: موجودی کالا | B32: =تاریخی!$C$21 -> 860000 | C32: =C14*مفروضات!$B$25/365 -> 1176274.8 | D32: =D14*مفروضات!$B$25/365 -> 1547801.9 | E32: =E14*مفروضات!$B$25/365 -> 2013878.4 | F32: =F14*مفروضات!$B$25/365 -> 2566688.7 | G32: =G14*مفروضات!$B$25/365 -> 3275776
A33: دارایی ثابت خالص | B33: =تاریخی!$C$22 -> 2500000 | C33: =B33-C47-C15 -> 2587500 | D33: =C33-D47-D15 -> 2767500 | E33: =D33-E47-E15 -> 3052350 | F33: =E33-F47-F15 -> 3449115 | G33: =F33-G47-G15 -> 3981703.5
A34: سایر دارایی‌ها | B34: =تاریخی!$C$23 -> 150000 | C34: =B34 -> 150000 | D34: =C34 -> 150000 | E34: =D34 -> 150000 | F34: =E34 -> 150000 | G34: =F34 -> 150000
A35: جمع دارایی‌ها | B35: =B30+B31+B32+B33+B34 -> 4630000 | C35: =C30+C31+C32+C33+C34 -> 5645804.1 | D35: =D30+D31+D32+D33+D34 -> 7025414.9 | E35: =E30+E31+E32+E33+E34 -> 8563352.4 | F35: =F30+F31+F32+F33+F34 -> 10694643 | G35: =G30+G31+G32+G33+G34 -> 13529700
A36: پرداختنی‌های تجاری | B36: =تاریخی!$C$25 -> 430000 | C36: =C14*مفروضات!$B$26/365 -> 588137.42 | D36: =D14*مفروضات!$B$26/365 -> 773900.97 | E36: =E14*مفروضات!$B$26/365 -> 1006939.2 | F36: =F14*مفروضات!$B$26/365 -> 1283344.3 | G36: =G14*مفروضات!$B$26/365 -> 1637888
A37: تسهیلات مالی | B37: =تاریخی!$C$26 -> 1000000 | C37: =B37+مفروضات!B15 -> 1000000 | D37: =C37+مفروضات!C15 -> 1000000 | E37: =D37+مفروضات!D15 -> 1000000 | F37: =E37+مفروضات!E15 -> 1000000 | G37: =F37+مفروضات!F15 -> 1000000
A38: سایر بدهی‌ها | B38: =تاریخی!$C$27 -> 200000 | C38: =B38 -> 200000 | D38: =C38 -> 200000 | E38: =D38 -> 200000 | F38: =E38 -> 200000 | G38: =F38 -> 200000
A39: حقوق مالکانه | B39: =تاریخی!$C$28 -> 3000000 | C39: =B39+C25-C28+مفروضات!B16 -> 3857666.7 | D39: =C39+D25-D28+مفروضات!C16 -> 5051514 | E39: =D39+E25-E28+مفروضات!D16 -> 6356413.2 | F39: =E39+F25-F28+مفروضات!E16 -> 8211298.6 | G39: =F39+G25-G28+مفروضات!F16 -> 10691812
A40: جمع بدهی‌ها و حقوق مالکانه | B40: =B36+B37+B38+B39 -> 4630000 | C40: =C36+C37+C38+C39 -> 5645804.1 | D40: =D36+D37+D38+D39 -> 7025414.9 | E40: =E36+E37+E38+E39 -> 8563352.4 | F40: =F36+F37+F38+F39 -> 10694643 | G40: =G36+G37+G38+G39 -> 13529700
...

Sheet ارزش‌گذاری
A1: ارزش‌گذاری: DCF، ضریب EV/EBITDA و دامنه ارزش
A2: میلیون ریال؛ ارزش هر سهم به ریال. نتیجه را به صورت دامنه بخوانید.
A4: نرخ تنزیل
A5: هزینه سرمایه سهام = نرخ بدون ریسک + صرف ریسک سهام + صرف ریسک خاص | B5: =مفروضات!$B$32+مفروضات!$B$33+مفروضات!$B$34 -> 0.39
A6: هزینه بدهی پس از مالیات | B6: =مفروضات!$B$35*(1-مفروضات!$B$37) -> 0.1725
A7: WACC اسمی | B7: =(1-مفروضات!$B$36)*B5+مفروضات!$B$36*B6 -> 0.3465
A8: WACC واقعی (فقط برای کنترل؛ معمولاً بین پنج تا ده درصد) | B8: =(1+B7)/(1+مفروضات!$B$38)-1 -> 0.0772
A9: رشد نهایی اسمی = (۱ + تورم بلندمدت) × (۱ + رشد واقعی) − ۱ | B9: =(1+مفروضات!$B$38)*(1+مفروضات!$B$39)-1 -> 0.2625
A10: کنترل: WACC باید از رشد نهایی بیشتر باشد | B10: =IF(B7>B9,"درست","خطا: نرخ تنزیل را بالا یا رشد را پایین ببرید") -> درست
A12: جریان نقد آزاد شرکت (FCFF)
A13: شرح | C13: سال اول | D13: سال دوم | E13: سال سوم | F13: سال چهارم | G13: سال پنجم
A14: سال (t) | C14: 1 | D14: 2 | E14: 3 | F14: 4 | G14: 5
A15: سود عملیاتی (EBIT) | C15: =مدل!C19 -> 1764902 | D15: =مدل!D19 -> 2473636.9 | E15: =مدل!E19 -> 3369703.2 | F15: =مدل!F19 -> 4444666.5 | G15: =مدل!G19 -> 5839452.9
A16: نرخ مؤثر مالیات | C16: =مفروضات!B13 -> 0.15 | D16: =مفروضات!C13 -> 0.15 | E16: =مفروضات!D13 -> 0.25 | F16: =مفروضات!E13 -> 0.25 | G16: =مفروضات!F13 -> 0.25
A17: EBIT × (۱ − نرخ مالیات) | C17: =C15*(1-C16) -> 1500166.7 | D17: =D15*(1-D16) -> 2102591.3 | E17: =E15*(1-E16) -> 2527277.4 | F17: =F15*(1-F16) -> 3333499.9 | G17: =G15*(1-G16) -> 4379589.7
A18: + استهلاک | C18: =مدل!C15 -> 250000 | D18: =مدل!D15 -> 258750 | E18: =مدل!E15 -> 276750 | F18: =مدل!F15 -> 305235 | G18: =مدل!G15 -> 344911.5
A19: − CAPEX | C19: =مدل!C47 -> -337500 | D19: =مدل!D47 -> -438750 | E19: =مدل!E47 -> -561600 | F19: =مدل!F47 -> -702000 | G19: =مدل!G47 -> -877500
A20: − افزایش سرمایه در گردش | C20: =مدل!C45 -> -481014.14 | D20: =مدل!D45 -> -573198.75 | E20: =مدل!E45 -> -720289.56 | F20: =مدل!F45 -> -856454.56 | G20: =مدل!G45 -> -1101357.3
A21: FCFF | C21: =C17+C18+C19+C20 -> 931652.56 | D21: =D17+D18+D19+D20 -> 1349392.6 | E21: =E17+E18+E19+E20 -> 1522137.9 | F21: =F17+F18+F19+F20 -> 2080280.3 | G21: =G17+G18+G19+G20 -> 2745643.9
A22: ضریب تنزیل = ۱ ÷ (۱ + WACC) به توان t | C22: =1/(1+$B$7)^C14 -> 0.74266617 | D22: =1/(1+$B$7)^D14 -> 0.55155304 | E22: =1/(1+$B$7)^E14 -> 0.40961979 | F22: =1/(1+$B$7)^F14 -> 0.30421076 | G22: =1/(1+$B$7)^G14 -> 0.22592704
A23: ارزش فعلی FCFF | C23: =C21*C22 -> 691906.84 | D23: =D21*D22 -> 744261.59 | E23: =E21*E22 -> 623497.79 | F23: =F21*F22 -> 632843.65 | G23: =G21*G22 -> 620315.19
A25: از ارزش شرکت تا ارزش هر سهم
A26: جمع ارزش فعلی سال‌های اول تا پنجم | B26: =SUM(C23:G23) -> 3312825.1
A27: ارزش نهایی در پایان سال پنجم | B27: =IF(B7>B9,G21*(1+B9)/(B7-B9),0) -> 41266373
A28: ارزش فعلی ارزش نهایی | B28: =B27*G22 -> 9323189.6
A29: ارزش کل شرکت (EV) | B29: =B26+B28 -> 12636015
A30: سهم ارزش نهایی از EV | B30: =IF(B29=0,0,B28/B29) -> 0.73782675
A31: خالص بدهی پایان سال پایه (تسهیلات − نقد) | B31: =مدل!B37-مدل!B30 -> 700000
A32: + سرمایه‌گذاری‌های غیرعملیاتی | B32: =مفروضات!$B$41 -> 0
A33: ارزش سهام | B33: =B29-B31+B32 -> 11936015
A34: تعداد سهام (میلیون) | B34: =مدل!B26 -> 4000
A35: ارزش هر سهم (ریال) | B35: =IF(B34=0,0,B33/B34) -> 2984.0037
A36: قیمت بازار (ریال) | B36: =مفروضات!$B$40 -> 2000
A37: فاصله ارزش تا قیمت (ارزش ÷ قیمت − ۱) | B37: =IF(B36=0,0,B35/B36-1) -> 0.49200183
A38: ضریب ضمنی ارزش نهایی (ارزش نهایی ÷ EBITDA سال پنجم) | B38: =IF(مدل!G20=0,0,B27/مدل!G20) -> 6.6726944
A40: حساسیت ارزش هر سهم (ریال) به WACC و رشد نهایی واقعی
A41: WACC اسمی ↓ / رشد نهایی واقعی → | B41: 0 | C41: 0.01 | D41: 0.02
A42: =$B$7+(-0.02) -> 0.3265 | B42: =IF($A42<=((1+مفروضات!$B$38)*(1+B$41)-1),0,(SUMPRODUCT($C$21:$G$21/(1+$A42)^$C$14:$G$14)+$G$21*(1+((1+مفروضات!$B$38)*(1+B$41)-1))/($A42-((1+مفروضات!$B$38)*(1+B$41)-1))/(1+$A42)^5-$B$31+$B$32)/$B$34) -> 3421.2745 | C42: =IF($A42<=((1+مفروضات!$B$38)*(1+C$41)-1),0,(SUMPRODUCT($C$21:$G$21/(1+$A42)^$C$14:$G$14)+$G$21*(1+((1+مفروضات!$B$38)*(1+C$41)-1))/($A42-((1+مفروضات!$B$38)*(1+C$41)-1))/(1+$A42)^5-$B$31+$B$32)/$B$34) -> 3987.2841 | D42: =IF($A42<=((1+مفروضات!$B$38)*(1+D$41)-1),0,(SUMPRODUCT($C$21:$G$21/(1+$A42)^$C$14:$G$14)+$G$21*(1+((1+مفروضات!$B$38)*(1+D$41)-1))/($A42-((1+مفروضات!$B$38)*(1+D$41)-1))/(1+$A42)^5-$B$31+$B$32)/$B$34) -> 4828.0557
A43: =$B$7+(-0.01) -> 0.3365 | B43: =IF($A43<=((1+مفروضات!$B$38)*(1+B$41)-1),0,(SUMPRODUCT($C$21:$G$21/(1+$A43)^$C$14:$G$14)+$G$21*(1+((1+مفروضات!$B$38)*(1+B$41)-1))/($A43-((1+مفروضات!$B$38)*(1+B$41)-1))/(1+$A43)^5-$B$31+$B$32)/$B$34) -> 2997.6244 | C43: =IF($A43<=((1+مفروضات!$B$38)*(1+C$41)-1),0,(SUMPRODUCT($C$21:$G$21/(1+$A43)^$C$14:$G$14)+$G$21*(1+((1+مفروضات!$B$38)*(1+C$41)-1))/($A43-((1+مفروضات!$B$38)*(1+C$41)-1))/(1+$A43)^5-$B$31+$B$32)/$B$34) -> 3417.7417 | D43: =IF($A43<=((1+مفروضات!$B$38)*(1+D$41)-1),0,(SUMPRODUCT($C$21:$G$21/(1+$A43)^$C$14:$G$14)+$G$21*(1+((1+مفروضات!$B$38)*(1+D$41)-1))/($A43-((1+مفروضات!$B$38)*(1+D$41)-1))/(1+$A43)^5-$B$31+$B$32)/$B$34) -> 4008.6384
A44: =$B$7+(0) -> 0.3465 | B44: =IF($A44<=((1+مفروضات!$B$38)*(1+B$41)-1),0,(SUMPRODUCT($C$21:$G$21/(1+$A44)^$C$14:$G$14)+$G$21*(1+((1+مفروضات!$B$38)*(1+B$41)-1))/($A44-((1+مفروضات!$B$38)*(1+B$41)-1))/(1+$A44)^5-$B$31+$B$32)/$B$34) -> 2661.999 | C44: =IF($A44<=((1+مفروضات!$B$38)*(1+C$41)-1),0,(SUMPRODUCT($C$21:$G$21/(1+$A44)^$C$14:$G$14)+$G$21*(1+((1+مفروضات!$B$38)*(1+C$41)-1))/($A44-((1+مفروضات!$B$38)*(1+C$41)-1))/(1+$A44)^5-$B$31+$B$32)/$B$34) -> 2984.0037 | D44: =IF($A44<=((1+مفروضات!$B$38)*(1+D$41)-1),0,(SUMPRODUCT($C$21:$G$21/(1+$A44)^$C$14:$G$14)+$G$21*(1+((1+مفروضات!$B$38)*(1+D$41)-1))/($A44-((1+مفروضات!$B$38)*(1+D$41)-1))/(1+$A44)^5-$B$31+$B$32)/$B$34) -> 3418.5974
...
